Workbook
Name aaa: #REF!
Name aaa: #REF!
Name aaa: #REF!
Name Anniversaire: #REF!,#REF!,#REF!,#REF!
Name Anniversaire: #REF!,#REF!,#REF!,#REF!
Name Anniversaire: #REF!,#REF!,#REF!,#REF!
Name bOH: #REF!,#REF!,#REF!,#REF!
Name bOH: #REF!,#REF!,#REF!,#REF!
Name bOH: #REF!,#REF!,#REF!,#REF!
Name CAP1E: #REF!
Name CAP1E: #REF!
Name CAP1E: #REF!
Name CapitFIXE: #REF!
Name CapitFIXE: #REF!
Name CapitFIXE: #REF!
Name CCC: #REF!
Name CCC: #REF!
Name CCC: #REF!
Name Changement_de_taux: #REF!
Name Changement_de_taux: #REF!
Name Changement_de_taux: #REF!
Name Cout_Total: #REF!
Name Cout_Total: #REF!
Name Cout_Total: #REF!
Name DATDB: #REF!
Name DATDB: #REF!
Name DATDB: #REF!
Name DebAmort: #REF!
Name DebAmort: #REF!
Name DebAmort: #REF!
Name Début_échéance: #REF!
Name Début_échéance: #REF!
Name Début_échéance: #REF!
Name Dernière_période: #REF!
Name Dernière_période: #REF!
Name Dernière_période: #REF!
Name Différé: #REF!
Name Différé: #REF!
Name Différé: #REF!
Name DiffSimple: #REF!
Name DiffSimple: #REF!
Name DiffSimple: #REF!
Name DiffTotal: #REF!
Name DiffTotal: #REF!
Name DiffTotal: #REF!
Name Durée: #REF!
Name Durée: #REF!
Name Durée: #REF!
Name EchFIXE: #REF!
Name EchFIXE: #REF!
Name EchFIXE: #REF!
Name FraisF: #REF!
Name FraisF: #REF!
Name FraisF: #REF!
Name FraisV: #REF!
Name FraisV: #REF!
Name FraisV: #REF!
Name Ijour: #REF!
Name Ijour: #REF!
Name Ijour: #REF!

Sheet Conta corrente
D2: SOMBRA RESORT BRASIL | F2: 48649-3 | H2: 43.730.206/0001-80 | I2: CNPJ
C4: R$ | D4: C/C Ordinario | F4: Banco do Brasil - Goianinha | I4: 1066-9
A5: Nr | B5: Date Comptable | C5: Anno | D5: Description | E5: E/U | F5: CATEGORIA | G5: TIPO | H5: Soggetto | I5: Total | J5: Solde
A6: 1 | B6: 44538 | C6: =IF(B6="","",YEAR(B6)) -> 2021 | D6: saldo anterior | I6: 0 | J6: =I6 -> 0
A7: =A6+1 -> 2 | B7: 44552 | C7: =IF(B7="","",YEAR(B7)) -> 2021 | D7: Pagamento contratto affitto | E7: ENTRADAS | F7: LOCACAO | G7: Produtos | H7: 140852-6 SCP - JM EMPREENDIMENTOS IMOBILIARIO SCP LTDA | I7: 600000 | J7: =IF(I7="",".",J6+I7) -> 600000
A8: =A7+1 -> 3 | B8: 44553 | C8: =IF(B8="","",YEAR(B8)) -> 2021 | D8: Aplicaçao | F8: INVESTIMENTOS | G8: Aplicaçao | H8: B.B. | I8: -600000 | J8: =IF(I8="",".",J7+I8) -> 0
A9: =A8+1 -> 4 | B9: 44558 | C9: =IF(B9="","",YEAR(B9)) -> 2021 | D9: Resgate | F9: INVESTIMENTOS | G9: Resgate | H9: B.B. | I9: 600000 | J9: =IF(I9="",".",J8+I9) -> 600000
A10: =A9+1 -> 5 | B10: 44558 | C10: =IF(B10="","",YEAR(B10)) -> 2021 | D10: Pagamento terreno | E10: SAIDAS | F10: IMOBILIZACAO | G10: Terreno | H10: SOMBRA FLORESTA | I10: -600000 | J10: =IF(I10="",".",J9+I10) -> 0
A11: =A10+1 -> 6 | B11: 44566 | C11: =IF(B11="","",YEAR(B11)) -> 2022 | D11: Resgate | F11: INVESTIMENTOS | G11: Resgate | H11: B.B. | I11: 60 | J11: =IF(I11="",".",J10+I11) -> 60
A12: =A11+1 -> 7 | B12: 44566 | C12: =IF(B12="","",YEAR(B12)) -> 2022 | D12: Tarifa Pacote de Serviços | E12: SAIDAS | F12: DESPESAS FINANCEIRAS | G12: Despesas Bancarias | H12: B.B. | I12: -60 | J12: =IF(I12="",".",J11+I12) -> 0
A13: =A12+1 -> 8 | B13: 44599 | C13: =IF(B13="","",YEAR(B13)) -> 2022 | D13: Tarifa Pacote de Serviços | E13: SAIDAS | F13: DESPESAS FINANCEIRAS | G13: Despesas Bancarias | H13: B.B. | I13: -10.82 | J13: =IF(I13="",".",J12+I13) -> -10.82
A14: =A13+1 -> 9 | B14: 44599 | C14: =IF(B14="","",YEAR(B14)) -> 2022 | D14: Resgate | F14: INVESTIMENTOS | G14: Resgate | H14: B.B. | I14: 10.82 | J14: =IF(I14="",".",J13+I14) -> 0
A15: =A14+1 -> 10 | B15: 44607 | C15: =IF(B15="","",YEAR(B15)) -> 2022 | D15: Pagamento contratto affitto | E15: ENTRADAS | F15: LOCACAO | G15: Produtos | H15: 140850-X - JM EMPREENDIMENTOS IMOB | I15: 183947.11 | J15: =IF(I15="",".",J14+I15) -> 183947.11
A16: =A15+1 -> 11 | B16: 44607 | C16: =IF(B16="","",YEAR(B16)) -> 2022 | D16: Tarifa Pacote de Serviços | E16: SAIDAS | F16: DESPESAS FINANCEIRAS | G16: Despesas Bancarias | H16: B.B. | I16: -55.18 | J16: =IF(I16="",".",J15+I16) -> 183891.93
A17: =A16+1 -> 12 | B17: 44608 | C17: =IF(B17="","",YEAR(B17)) -> 2022 | D17: Pagamento contratto affitto | E17: ENTRADAS | F17: LOCACAO | G17: Produtos | H17: 140850-X - JM EMPREENDIMENTOS IMOB | I17: 200000 | J17: =IF(I17="",".",J16+I17) -> 383891.93
A18: =A17+1 -> 13 | B18: 44609 | C18: =IF(B18="","",YEAR(B18)) -> 2022 | D18: Pagamento contratto affitto | E18: ENTRADAS | F18: LOCACAO | G18: Produtos | H18: 140850-X - JM EMPREENDIMENTOS IMOB | I18: 200000 | J18: =IF(I18="",".",J17+I18) -> 583891.93 | K18: -72.87 | L18: Taxa de localizaçao 2021
A19: =A18+1 -> 14 | B19: 44627 | C19: =IF(B19="","",YEAR(B19)) -> 2022 | D19: Tarifa Pacote de Serviços | E19: SAIDAS | F19: DESPESAS FINANCEIRAS | G19: Despesas Bancarias | H19: B.B. | I19: -66 | J19: =IF(I19="",".",J18+I19) -> 583825.93 | K19: -320.78 | L19: Taxa de localizaçao 2022
A20: =A19+1 -> 15 | B20: 44630 | C20: =IF(B20="","",YEAR(B20)) -> 2022 | D20: Impostos e Taxas | E20: SAIDAS | F20: DESPESAS TRIBUTARIAS | G20: Taxa de Localizaçao 2021 | H20: PREF MUNICIPAL DE NATAL | I20: -72.87 | J20: =IF(I20="",".",J19+I20) -> 583753.06 | K20: =SUM(K18:K19) -> -393.65
A21: =A20+1 -> 16 | B21: 44631 | C21: =IF(B21="","",YEAR(B21)) -> 2022 | D21: Impostos e Taxas | E21: SAIDAS | F21: DESPESAS TRIBUTARIAS | G21: Taxa de Localizaçao 2022 | H21: PREF MUNICIPAL DE NATAL | I21: -320.78 | J21: =IF(I21="",".",J20+I21) -> 583432.28 | K21: -23.37 | L21: Juros e multa
A22: =A21+1 -> 17 | B22: 44632 | C22: =IF(B22="","",YEAR(B22)) -> 2022 | D22: Impostos e Taxas | E22: SAIDAS | F22: DESPESAS TRIBUTARIAS | G22: Juros e Multa | H22: PREF MUNICIPAL DE NATAL | I22: -23.37 | J22: =IF(I22="",".",J21+I22) -> 583408.91 | K22: =SUM(K20:K21) -> -417.02
A23: =A22+1 -> 18 | B23: 44656 | C23: =IF(B23="","",YEAR(B23)) -> 2022 | D23: Tarifa Pacote de Serviços | E23: SAIDAS | F23: DESPESAS FINANCEIRAS | G23: Despesas Bancarias | H23: B.B. | I23: -66 | J23: =IF(I23="",".",J22+I23) -> 583342.91
A24: =A23+1 -> 19 | B24: 44686 | C24: =IF(B24="","",YEAR(B24)) -> 2022 | D24: Tarifa Pacote de Serviços | E24: SAIDAS | F24: DESPESAS FINANCEIRAS | G24: Despesas Bancarias | H24: B.B. | I24: -66 | J24: =IF(I24="",".",J23+I24) -> 583276.91
A25: =A24+1 -> 20 | B25: 44718 | C25: =IF(B25="","",YEAR(B25)) -> 2022 | D25: Tarifa Pacote de Serviços | E25: SAIDAS | F25: DESPESAS FINANCEIRAS | G25: Despesas Bancarias | H25: B.B. | I25: -66 | J25: =IF(I25="",".",J24+I25) -> 583210.91
A26: =A25+1 -> 21 | B26: 44735 | C26: =IF(B26="","",YEAR(B26)) -> 2022 | D26: Aplicaçao | F26: INVESTIMENTOS | G26: Aplicaçao | H26: B.B. | I26: -583210.91 | J26: =IF(I26="",".",J25+I26) -> -1.1641532e-10
A27: =A26+1 -> 22 | B27: 44748 | C27: =IF(B27="","",YEAR(B27)) -> 2022 | D27: Tarifa Pacote de Serviços | E27: SAIDAS | F27: DESPESAS FINANCEIRAS | G27: Despesas Bancarias | H27: B.B. | I27: -66 | J27: =IF(I27="",".",J26+I27) -> -66
A28: =A27+1 -> 23 | B28: 44748 | C28: =IF(B28="","",YEAR(B28)) -> 2022 | D28: Resgate | F28: INVESTIMENTOS | G28: Resgate | H28: B.B. | I28: 66 | J28: =IF(I28="",".",J27+I28) -> -1.1641532e-10
A29: =A28+1 -> 24 | B29: 44778 | C29: =IF(B29="","",YEAR(B29)) -> 2022 | D29: Tarifa Pacote de Serviços | E29: SAIDAS | F29: DESPESAS FINANCEIRAS | G29: Despesas Bancarias | H29: B.B. | I29: -66 | J29: =IF(I29="",".",J28+I29) -> -66
A30: =A29+1 -> 25 | B30: 44778 | C30: =IF(B30="","",YEAR(B30)) -> 2022 | D30: Resgate | F30: INVESTIMENTOS | G30: Resgate | H30: B.B. | I30: 66 | J30: =IF(I30="",".",J29+I30) -> -1.1641532e-10
A31: =A30+1 -> 26 | B31: 44809 | C31: =IF(B31="","",YEAR(B31)) -> 2022 | D31: Tarifa Pacote de Serviços | E31: SAIDAS | F31: DESPESAS FINANCEIRAS | G31: Despesas Bancarias | H31: B.B. | I31: -66 | J31: =IF(I31="",".",J30+I31) -> -66
A32: =A31+1 -> 27 | B32: 44809 | C32: =IF(B32="","",YEAR(B32)) -> 2022 | D32: Resgate | F32: INVESTIMENTOS | G32: Resgate | H32: B.B. | I32: 66 | J32: =IF(I32="",".",J31+I32) -> -1.1641532e-10
A33: =A32+1 -> 28 | B33: 44839 | C33: =IF(B33="","",YEAR(B33)) -> 2022 | D33: Tarifa Pacote de Serviços | E33: SAIDAS | F33: DESPESAS FINANCEIRAS | G33: Despesas Bancarias | H33: B.B. | I33: -66 | J33: =IF(I33="",".",J32+I33) -> -66
A34: =A33+1 -> 29 | B34: 44839 | C34: =IF(B34="","",YEAR(B34)) -> 2022 | D34: Resgate | F34: INVESTIMENTOS | G34: Resgate | H34: B.B. | I34: 66 | J34: =IF(I34="",".",J33+I34) -> -1.1641532e-10
A35: =A34+1 -> 30 | B35: 44872 | C35: =IF(B35="","",YEAR(B35)) -> 2022 | D35: Tarifa Pacote de Serviços | E35: SAIDAS | F35: DESPESAS FINANCEIRAS | G35: Despesas Bancarias | H35: B.B. | I35: -66 | J35: =IF(I35="",".",J34+I35) -> -66
A36: =A35+1 -> 31 | B36: 44872 | C36: =IF(B36="","",YEAR(B36)) -> 2022 | D36: Resgate | F36: INVESTIMENTOS | G36: Resgate | H36: B.B. | I36: 66 | J36: =IF(I36="",".",J35+I36) -> -1.1641532e-10
A37: =A36+1 -> 32 | B37: 44900 | C37: =IF(B37="","",YEAR(B37)) -> 2022 | D37: Tarifa Pacote de Serviços | E37: SAIDAS | F37: DESPESAS FINANCEIRAS | G37: Despesas Bancarias | H37: B.B. | I37: -66 | J37: =IF(I37="",".",J36+I37) -> -66
A38: =A37+1 -> 33 | B38: 44900 | C38: =IF(B38="","",YEAR(B38)) -> 2022 | D38: Resgate | F38: INVESTIMENTOS | G38: Resgate | H38: B.B. | I38: 66 | J38: =IF(I38="",".",J37+I38) -> -1.1641532e-10
A39: =A38+1 -> 34 | B39: 44918 | C39: =IF(B39="","",YEAR(B39)) -> 2022 | D39: 50% Traduzione giurata dello Statuto | E39: SAIDAS | F39: DESPESAS GERAIS | G39: Varias | H39: Antonio Francisco Alves Ro | I39: -1050 | J39: =IF(I39="",".",J38+I39) -> -1050
A40: =A39+1 -> 35 | B40: 44918 | C40: =IF(B40="","",YEAR(B40)) -> 2022 | D40: Resgate | F40: INVESTIMENTOS | G40: Resgate | H40: B.B. | I40: 1050 | J40: =IF(I40="",".",J39+I40) -> -1.1641532e-10
A41: =A40+1 -> 36 | B41: 44924 | C41: =IF(B41="","",YEAR(B41)) -> 2022 | D41: Pagamento contratto affitto | E41: ENTRADAS | F41: LOCACAO | G41: Produtos | H41: 140852-6 SCP - JM EMPREENDIMENTOS IMOBILIARIO SCP LTDA | I41: 255109.77 | J41: =IF(I41="",".",J40+I41) -> 255109.77
A42: =A41+1 -> 37 | B42: 44931 | C42: =IF(B42="","",YEAR(B42)) -> 2023 | D42: Tarifa Pacote de Serviços | E42: SAIDAS | F42: DESPESAS FINANCEIRAS | G42: Despesas Bancarias | H42: B.B. | I42: -69 | J42: =IF(I42="",".",J41+I42) -> 255040.77
...

Sheet Resumo BB ORD
A6: Sum of Total | D6: Anno
A7: CATEGORIA | B7: TIPO | C7: Soggetto | D7: 2021 | E7: 2022 | F7: 2023 | G7: 2024 | H7: 2025 | I7: 2026 | J7: Totale complessivo
A8: INVESTIMENTOS
B9: Aplicaçao
C10: B.B. | D10: -600000 | E10: -583210.91 | F10: -255040.77 | H10: -597295.96 | J10: -2035547.6
B12: Resgate
C13: B.B. | D13: 600000 | E13: 1516.82 | F13: 2812 | G13: 23022.07 | H13: 92862.17 | I13: 12024.75 | J13: 732237.81
A15: LOCACAO
B16: Produtos
C17: 140852-6 SCP - JM EMPREENDIMENTOS IMOBILIARIO SCP LTDA | D17: 600000 | E17: 255109.77 | H17: 617509.26 | I17: 43156.04 | J17: 1515775.1
C18: 140850-X - JM EMPREENDIMENTOS IMOB | E18: 583947.11 | J18: 583947.11
A20: IMOBILIZACAO
B21: Terreno
C22: SOMBRA FLORESTA | D22: -600000 | J22: -600000
A24: DESPESAS FINANCEIRAS
B25: Despesas Bancarias
C26: B.B. | E26: -786 | F26: -831 | G26: -729 | H26: -925.6 | I26: -791.1 | J26: -4062.7
A28: DESPESAS TRIBUTARIAS
B29: Juros e Multa
C30: PREF MUNICIPAL DE NATAL | E30: -23.37 | J30: -23.37
B32: Taxa de Localizaçao 2021
C33: PREF MUNICIPAL DE NATAL | E33: -72.87 | J33: -72.87
B35: Taxa de Localizaçao 2022
C36: PREF MUNICIPAL DE NATAL | E36: -320.78 | J36: -320.78
B38: Taxa de Localizaçao 2023
C39: PREF MUNICIPAL DE NATAL | G39: -408.82 | J39: -408.82
B41: Taxa de Localizaçao 2024
C42: PREF MUNICIPAL DE NATAL | G42: -408.78 | J42: -408.78
B44: Taxa de Localizaçao 2025
C45: PREF MUNICIPAL DE NATAL | H45: -378.61 | J45: -378.61
B47: Taxa de Localizaçao 2026
C48: PREF MUNICIPAL DE NATAL | I48: -398.75 | J48: -398.75
A50: DESPESAS GERAIS
B51: Varias
C52: Antonio Francisco Alves Ro | E52: -1050 | J52: -1050
C53: ONE Empreendimentos Serviços | F53: -850 | G53: -850 | H53: -898.2 | J53: -2598.2
C54: Igor R.R. Franca Sociedade - Junta Comercial | F54: -1200 | J54: -1200
C55: Natal - Cartorio 2 Oficio Nota | G55: -1049.08 | J55: -1049.08
C56: Mac Madeira Ltd | G56: -421.6 | J56: -421.6
C57: Magnolia Melo de Souza | G57: -3700 | H57: -4800 | J57: -8500
...

Sheet Conto Investimento
D2: SOMBRA RESORT BRASIL | F2: 48649-3 | I2: 43.730.206/0001-80 | J2: CNPJ:
I3: 43.617.343/0001-02 | J3: CNPJ Conta Agil:
C4: R$ | D4: C/C Investimento Fundos | F4: Banco do Brasil - Goianinha | I4: 1066-9
A5: Nr | B5: Date Comptable | C5: Anno | D5: Description | E5: E/U | F5: CATEGORIA | G5: TIPO | H5: Descrizione | I5: Total | J5: Solde
A6: 1 | B6: 44530 | C6: =IF(B6="","",YEAR(B6)) -> 2021 | D6: saldo anterior | I6: 0 | J6: =I6 -> 0
A7: =A6+1 -> 2 | B7: 44553 | C7: =IF(B7="","",YEAR(B7)) -> 2021 | D7: Aplicaçao | F7: INVESTIMENTOS | G7: Aplicaçao | H7: B.B. | I7: 600000 | J7: =IF(I7="",".",J6+I7) -> 600000
A8: =A7+1 -> 3 | B8: 44558 | C8: =IF(B8="","",YEAR(B8)) -> 2021 | D8: Resgate | F8: INVESTIMENTOS | G8: Resgate | H8: B.B. | I8: -600000 | J8: =IF(I8="",".",J7+I8) -> 0
A9: =A8+1 -> 4 | B9: 44561 | C9: =IF(B9="","",YEAR(B9)) -> 2021 | D9: Rendimento Bruto | E9: ENTRADAS | F9: JUROS | G9: Receitas Financeiras | I9: 536.34 | J9: =IF(I9="",".",J8+I9) -> 536.34
A10: =A9+1 -> 5 | B10: 44561 | C10: =IF(B10="","",YEAR(B10)) -> 2021 | D10: Imposto de Renda | E10: SAIDAS | F10: DESPESAS TRIBUTARIAS | G10: IRRF | I10: -20.5 | J10: =IF(I10="",".",J9+I10) -> 515.84
A11: =A10+1 -> 6 | B11: 44561 | C11: =IF(B11="","",YEAR(B11)) -> 2021 | D11: I.O.F. | E11: SAIDAS | F11: DESPESAS TRIBUTARIAS | G11: IOF Bancario | I11: -445.05 | J11: =IF(I11="",".",J10+I11) -> 70.79
A12: =A11+1 -> 7 | B12: 44566 | C12: =IF(B12="","",YEAR(B12)) -> 2022 | D12: Resgate | F12: RESGATE | G12: Despesas Bancarias | H12: B.B. | I12: -60 | J12: =IF(I12="",".",J11+I12) -> 10.79
A13: =A12+1 -> 8 | B13: 44592 | C13: =IF(B13="","",YEAR(B13)) -> 2022 | D13: Rendimento Bruto | E13: ENTRADAS | F13: JUROS | G13: Receitas Financeiras | I13: 0.13 | J13: =IF(I13="",".",J12+I13) -> 10.92
A14: =A13+1 -> 9 | B14: 44592 | C14: =IF(B14="","",YEAR(B14)) -> 2022 | D14: Imposto de Renda | E14: SAIDAS | F14: DESPESAS TRIBUTARIAS | G14: IRRF | I14: -0.01 | J14: =IF(I14="",".",J13+I14) -> 10.91
A15: =A14+1 -> 10 | B15: 44592 | C15: =IF(B15="","",YEAR(B15)) -> 2022 | D15: I.O.F. | E15: SAIDAS | F15: DESPESAS TRIBUTARIAS | G15: IOF Bancario | I15: -0.08 | J15: =IF(I15="",".",J14+I15) -> 10.83
A16: =A15+1 -> 11 | B16: 44599 | C16: =IF(B16="","",YEAR(B16)) -> 2022 | D16: Resgate | F16: RESGATE | G16: Despesas Bancarias | H16: B.B. | I16: -10.82 | J16: =IF(I16="",".",J15+I16) -> 0.01
A17: =A16+1 -> 12 | B17: 44617 | C17: =IF(B17="","",YEAR(B17)) -> 2022 | D17: Rendimento Bruto | E17: ENTRADAS | F17: JUROS | G17: Receitas Financeiras | I17: 0.01 | J17: =IF(I17="",".",J16+I17) -> 0.02
A18: =A17+1 -> 13 | B18: 44617 | C18: =IF(B18="","",YEAR(B18)) -> 2022 | D18: Imposto de Renda | E18: SAIDAS | F18: DESPESAS TRIBUTARIAS | G18: IRRF | I18: -0.02 | J18: =IF(I18="",".",J17+I18) -> 2.1104646e-14
A19: =A18+1 -> 14 | B19: 44735 | C19: =IF(B19="","",YEAR(B19)) -> 2022 | D19: Aplicaçao | F19: INVESTIMENTOS | G19: Aplicaçao | H19: B.B. | I19: 583210.91 | J19: =IF(I19="",".",J18+I19) -> 583210.91
A20: =A19+1 -> 15 | B20: 44742 | C20: =IF(B20="","",YEAR(B20)) -> 2022 | D20: Rendimento Bruto | E20: ENTRADAS | F20: JUROS | G20: Receitas Financeiras | I20: 1207.1 | J20: =IF(I20="",".",J19+I20) -> 584418.01
A21: =A20+1 -> 16 | B21: 44748 | C21: =IF(B21="","",YEAR(B21)) -> 2022 | D21: Resgate | F21: RESGATE | G21: Despesas Bancarias | H21: B.B. | I21: -66 | J21: =IF(I21="",".",J20+I21) -> 584352.01
A22: =A21+1 -> 17 | B22: 44771 | C22: =IF(B22="","",YEAR(B22)) -> 2022 | D22: Rendimento Bruto | E22: ENTRADAS | F22: JUROS | G22: Receitas Financeiras | I22: 5089.39 | J22: =IF(I22="",".",J21+I22) -> 589441.4 | K22: =(I22+I23+I24)/J20*12 -> 0.10449863
A23: =A22+1 -> 18 | B23: 44771 | C23: =IF(B23="","",YEAR(B23)) -> 2022 | D23: Imposto de Renda | E23: SAIDAS | F23: DESPESAS TRIBUTARIAS | G23: IRRF | I23: -0.02 | J23: =IF(I23="",".",J22+I23) -> 589441.38
A24: =A23+1 -> 19 | B24: 44771 | C24: =IF(B24="","",YEAR(B24)) -> 2022 | D24: I.O.F. | E24: SAIDAS | F24: DESPESAS TRIBUTARIAS | G24: IOF Bancario | I24: -0.13 | J24: =IF(I24="",".",J23+I24) -> 589441.25
A25: =A24+1 -> 20 | B25: 44778 | C25: =IF(B25="","",YEAR(B25)) -> 2022 | D25: Resgate | F25: RESGATE | G25: Despesas Bancarias | H25: B.B. | I25: -66 | J25: =IF(I25="",".",J24+I25) -> 589375.25
A26: =A25+1 -> 21 | B26: 44804 | C26: =IF(B26="","",YEAR(B26)) -> 2022 | D26: Rendimento Bruto | E26: ENTRADAS | F26: JUROS | G26: Receitas Financeiras | I26: 5849.96 | J26: =IF(I26="",".",J25+I26) -> 595225.21 | K26: =(I26+I27)/J24*12 -> 0.11909136
A27: =A26+1 -> 22 | B27: 44804 | C27: =IF(B27="","",YEAR(B27)) -> 2022 | D27: Imposto de Renda | E27: SAIDAS | F27: DESPESAS TRIBUTARIAS | G27: IRRF | I27: -0.18 | J27: =IF(I27="",".",J26+I27) -> 595225.03
A28: =A27+1 -> 23 | B28: 44809 | C28: =IF(B28="","",YEAR(B28)) -> 2022 | D28: Resgate | F28: RESGATE | G28: Despesas Bancarias | H28: B.B. | I28: -66 | J28: =IF(I28="",".",J27+I28) -> 595159.03
A29: =A28+1 -> 24 | B29: 44834 | C29: =IF(B29="","",YEAR(B29)) -> 2022 | D29: Rendimento Bruto | E29: ENTRADAS | F29: JUROS | G29: Receitas Financeiras | I29: 5442.88 | J29: =IF(I29="",".",J28+I29) -> 600601.91 | K29: =(I29+I30)/J27*12 -> 0.10972442
A30: =A29+1 -> 25 | B30: 44834 | C30: =IF(B30="","",YEAR(B30)) -> 2022 | D30: Imposto de Renda | E30: SAIDAS | F30: DESPESAS TRIBUTARIAS | G30: IRRF | I30: -0.32 | J30: =IF(I30="",".",J29+I30) -> 600601.59
A31: =A30+1 -> 26 | B31: 44839 | C31: =IF(B31="","",YEAR(B31)) -> 2022 | D31: Resgate | F31: RESGATE | G31: Despesas Bancarias | H31: B.B. | I31: -66 | J31: =IF(I31="",".",J30+I31) -> 600535.59
A32: =A31+1 -> 27 | B32: 44865 | C32: =IF(B32="","",YEAR(B32)) -> 2022 | D32: Rendimento Bruto | E32: ENTRADAS | F32: JUROS | G32: Receitas Financeiras | I32: 5248.75 | J32: =IF(I32="",".",J31+I32) -> 605784.34 | K32: =(I32+I33)/J30*12 -> 0.10486086
A33: =A32+1 -> 28 | B33: 44865 | C33: =IF(B33="","",YEAR(B33)) -> 2022 | D33: Imposto de Renda | E33: SAIDAS | F33: DESPESAS TRIBUTARIAS | G33: IRRF | I33: -0.45 | J33: =IF(I33="",".",J32+I33) -> 605783.89
A34: =A33+1 -> 29 | B34: 44872 | C34: =IF(B34="","",YEAR(B34)) -> 2022 | D34: Resgate | F34: RESGATE | G34: Despesas Bancarias | H34: B.B. | I34: -66 | J34: =IF(I34="",".",J33+I34) -> 605717.89
A35: =A34+1 -> 30 | B35: 44895 | C35: =IF(B35="","",YEAR(B35)) -> 2022 | D35: Rendimento Bruto | E35: ENTRADAS | F35: JUROS | G35: Receitas Financeiras | I35: 5202.77 | J35: =IF(I35="",".",J34+I35) -> 610920.66
A36: =A35+1 -> 31 | B36: 44895 | C36: =IF(B36="","",YEAR(B36)) -> 2022 | D36: Imposto de Renda | E36: SAIDAS | F36: DESPESAS TRIBUTARIAS | G36: IRRF | I36: -5607.32 | J36: =IF(I36="",".",J35+I36) -> 605313.34
A37: =A36+1 -> 32 | B37: 44900 | C37: =IF(B37="","",YEAR(B37)) -> 2022 | D37: Resgate | F37: RESGATE | G37: Despesas Bancarias | H37: B.B. | I37: -66 | J37: =IF(I37="",".",J36+I37) -> 605247.34
A38: =A37+1 -> 33 | B38: 44918 | C38: =IF(B38="","",YEAR(B38)) -> 2022 | D38: Resgate | F38: RESGATE | G38: Despesas Gerais | H38: B.B. | I38: -1050 | J38: =IF(I38="",".",J37+I38) -> 604197.34
A39: =A38+1 -> 34 | B39: 44925 | C39: =IF(B39="","",YEAR(B39)) -> 2022 | D39: Rendimento Bruto | E39: ENTRADAS | F39: JUROS | G39: Receitas Financeiras | I39: 5739.48 | J39: =IF(I39="",".",J38+I39) -> 609936.82 | K39: =(I39+I40)/J36*12 -> 0.11375008
A40: =A39+1 -> 35 | B40: 44925 | C40: =IF(B40="","",YEAR(B40)) -> 2022 | D40: Imposto de Renda | E40: SAIDAS | F40: DESPESAS TRIBUTARIAS | G40: IRRF | I40: -1.61 | J40: =IF(I40="",".",J39+I40) -> 609935.21
A41: =A40+1 -> 36 | B41: 44957 | C41: =IF(B41="","",YEAR(B41)) -> 2023 | D41: Rendimento Bruto | E41: ENTRADAS | F41: JUROS | G41: Receitas Financeiras | I41: 5802.12 | J41: =IF(I41="",".",J40+I41) -> 615737.33 | K41: =(I41)/J40*12 -> 0.11415219
...

Sheet Resumo BB INV
A3: Sum of Total | C3: Anno
A4: CATEGORIA | B4: TIPO | C4: 2021 | D4: 2022 | E4: 2023 | F4: 2024 | G4: 2025 | H4: 2026 | I4: Totale complessivo
A5: INVESTIMENTOS
B6: Aplicaçao | C6: 600000 | D6: 583210.91 | E6: 255040.77 | G6: 597295.96 | I6: 2035547.6
B7: Resgate | C7: -600000 | I7: -600000
A9: JUROS
B10: Receitas Financeiras | C10: 536.34 | D10: 33780.47 | E10: 90650.19 | F10: 80942.61 | G10: 135991.31 | H10: 141245.5 | I10: 483146.42
A12: DESPESAS TRIBUTARIAS
B13: IOF Bancario | C13: -445.05 | D13: -0.21 | I13: -445.26
B14: IRRF | C14: -20.5 | D14: -5609.93 | E14: -17894.58 | F14: -16073.35 | G14: -25469.15 | H14: -18588.53 | I14: -83656.04
A16: RESGATE
B17: Despesas Gerais | D17: -1050 | E17: -2050 | F17: -20209.99 | G17: -30788.37 | H17: -12024.75 | I17: -66123.11
B18: Cessione Credito | G18: -62000 | I18: -62000
B19: Despesas Bancarias | D19: -466.82 | E19: -762 | F19: -2812.08 | G19: -73.8 | I19: -4114.7
A21: Totale complessivo | C21: 70.79 | D21: 609864.42 | E21: 324984.38 | F21: 41847.19 | G21: 614955.95 | H21: 110632.22 | I21: 1702354.9
E26: RENDIMENTO FINANCIERO
E27: ANOS | F27: JUROS | G27: IMPOSTOS | H27: % IMP
E28: =C4 -> 2021 | F28: =C10 -> 536.34 | G28: =C13+C14 -> -465.55 | H28: =-G28/F28 -> 0.86801283
E29: =D4 -> 2022 | F29: =D10 -> 33780.47 | G29: =D13+D14 -> -5610.14 | H29: =-G29/F29 -> 0.16607643
E30: =E4 -> 2023 | F30: =E10 -> 90650.19 | G30: =E13+E14 -> -17894.58 | H30: =-G30/F30 -> 0.19740256
E31: =F4 -> 2024 | F31: =F10 -> 80942.61 | G31: =+F13+F14 -> -16073.35 | H31: =-G31/F31 -> 0.19857712
E32: =G4 -> 2025 | F32: =G10 -> 135991.31 | G32: =+G13+G14 -> -25469.15 | H32: =-G32/F32 -> 0.18728513
E33: =H4 -> 2026 | F33: =H10 -> 141245.5 | G33: =H13+H14 -> -18588.53 | H33: =-G33/F33 -> 0.13160441
E36: TOTAL | F36: =SUM(F28:F35) -> 483146.42 | G36: =SUM(G28:G35) -> -84101.3 | H36: =-G36/F36 -> 0.17407001

Sheet Consolidato
A1: Nr | B1: Date Comptable | C1: Anno | D1: Description | E1: E/U | F1: CATEGORIA | G1: TIPO | H1: Soggetto | I1: Total | J1: Solde
A2: 1 | B2: 44538 | C2: =IF(B2="","",YEAR(B2)) -> 2021 | D2: saldo anterior | I2: 0 | J2: =I2 -> 0
A3: =A2+1 -> 2 | B3: 44552 | C3: =IF(B3="","",YEAR(B3)) -> 2021 | D3: Transferencia recebida | E3: ENTRADAS | F3: LOCACAO | G3: Produtos | H3: JM EMPREENDIMENTOS IMOBILIARIO SCP LTDA | I3: 600000 | J3: =IF(I3="",".",J2+I3) -> 600000
A4: =A3+1 -> 3 | B4: 44553 | C4: =IF(B4="","",YEAR(B4)) -> 2021 | D4: Aplicaçao | F4: INVESTIMENTOS | G4: Aplicaçao | H4: B.B. | I4: -600000 | J4: =IF(I4="",".",J3+I4) -> 0
A5: =A4+1 -> 4 | B5: 44558 | C5: =IF(B5="","",YEAR(B5)) -> 2021 | D5: Resgate | F5: INVESTIMENTOS | G5: Resgate | H5: B.B. | I5: 600000 | J5: =IF(I5="",".",J4+I5) -> 600000
A6: =A5+1 -> 5 | B6: 44558 | C6: =IF(B6="","",YEAR(B6)) -> 2021 | D6: Pagamento terreno | E6: SAIDAS | F6: IMOBILIZACAO | G6: Terreno | H6: SOMBRA FLORESTA | I6: -600000 | J6: =IF(I6="",".",J5+I6) -> 0
A7: =A6+1 -> 6 | B7: 44566 | C7: =IF(B7="","",YEAR(B7)) -> 2022 | D7: Resgate | F7: INVESTIMENTOS | G7: Resgate | H7: B.B. | I7: 60 | J7: =IF(I7="",".",J6+I7) -> 60
A8: =A7+1 -> 7 | B8: 44566 | C8: =IF(B8="","",YEAR(B8)) -> 2022 | D8: Tarifa Pacote de Serviços | E8: SAIDAS | F8: DESPESAS FINANCEIRAS | G8: Despesas Bancarias | H8: B.B. | I8: -60 | J8: =IF(I8="",".",J7+I8) -> 0
A9: =A8+1 -> 8 | B9: 44599 | C9: =IF(B9="","",YEAR(B9)) -> 2022 | D9: Tarifa Pacote de Serviços | E9: SAIDAS | F9: DESPESAS FINANCEIRAS | G9: Despesas Bancarias | H9: B.B. | I9: -10.82 | J9: =IF(I9="",".",J8+I9) -> -10.82
A10: =A9+1 -> 9 | B10: 44599 | C10: =IF(B10="","",YEAR(B10)) -> 2022 | D10: Resgate | F10: INVESTIMENTOS | G10: Resgate | H10: B.B. | I10: 10.82 | J10: =IF(I10="",".",J9+I10) -> 0
A11: =A10+1 -> 10 | B11: 44607 | C11: =IF(B11="","",YEAR(B11)) -> 2022 | D11: Transferencia recebida | E11: ENTRADAS | F11: LOCACAO | G11: Produtos | H11: JM EMPREENDIMENTOS IMOB | I11: 183947.11 | J11: =IF(I11="",".",J10+I11) -> 183947.11
A12: =A11+1 -> 11 | B12: 44607 | C12: =IF(B12="","",YEAR(B12)) -> 2022 | D12: Tarifa Pacote de Serviços | E12: SAIDAS | F12: DESPESAS FINANCEIRAS | G12: Despesas Bancarias | H12: B.B. | I12: -55.18 | J12: =IF(I12="",".",J11+I12) -> 183891.93
A13: =A12+1 -> 12 | B13: 44608 | C13: =IF(B13="","",YEAR(B13)) -> 2022 | D13: Transferencia recebida | E13: ENTRADAS | F13: LOCACAO | G13: Produtos | H13: JM EMPREENDIMENTOS IMOB | I13: 200000 | J13: =IF(I13="",".",J12+I13) -> 383891.93
A14: =A13+1 -> 13 | B14: 44609 | C14: =IF(B14="","",YEAR(B14)) -> 2022 | D14: Transferencia recebida | E14: ENTRADAS | F14: LOCACAO | G14: Produtos | H14: JM EMPREENDIMENTOS IMOB | I14: 200000 | J14: =IF(I14="",".",J13+I14) -> 583891.93 | K14: -72.87 | L14: Taxa de localizaçao 2021
A15: =A14+1 -> 14 | B15: 44627 | C15: =IF(B15="","",YEAR(B15)) -> 2022 | D15: Tarifa Pacote de Serviços | E15: SAIDAS | F15: DESPESAS FINANCEIRAS | G15: Despesas Bancarias | H15: B.B. | I15: -66 | J15: =IF(I15="",".",J14+I15) -> 583825.93 | K15: -320.78 | L15: Taxa de localizaçao 2022
A16: =A15+1 -> 15 | B16: 44630 | C16: =IF(B16="","",YEAR(B16)) -> 2022 | D16: Impostos | E16: SAIDAS | F16: DESPESAS TRIBUTARIAS | G16: Taxa de Localizaçao 2021 | H16: PREF MUNICIPAL DE NATAL | I16: -72.87 | J16: =IF(I16="",".",J15+I16) -> 583753.06 | K16: =SUM(K14:K15) -> -393.65
A17: =A16+1 -> 16 | B17: 44631 | C17: =IF(B17="","",YEAR(B17)) -> 2022 | D17: Impostos | E17: SAIDAS | F17: DESPESAS TRIBUTARIAS | G17: Taxa de Localizaçao 2022 | H17: PREF MUNICIPAL DE NATAL | I17: -320.78 | J17: =IF(I17="",".",J16+I17) -> 583432.28 | K17: -23.37 | L17: Juros e multa
A18: =A17+1 -> 17 | B18: 44632 | C18: =IF(B18="","",YEAR(B18)) -> 2022 | D18: Impostos | E18: SAIDAS | F18: DESPESAS TRIBUTARIAS | G18: Juros e Multa | H18: PREF MUNICIPAL DE NATAL | I18: -23.37 | J18: =IF(I18="",".",J17+I18) -> 583408.91 | K18: =SUM(K16:K17) -> -417.02
A19: =A18+1 -> 18 | B19: 44656 | C19: =IF(B19="","",YEAR(B19)) -> 2022 | D19: Tarifa Pacote de Serviços | E19: SAIDAS | F19: DESPESAS FINANCEIRAS | G19: Despesas Bancarias | H19: B.B. | I19: -66 | J19: =IF(I19="",".",J18+I19) -> 583342.91
A20: =A19+1 -> 19 | B20: 44686 | C20: =IF(B20="","",YEAR(B20)) -> 2022 | D20: Tarifa Pacote de Serviços | E20: SAIDAS | F20: DESPESAS FINANCEIRAS | G20: Despesas Bancarias | H20: B.B. | I20: -66 | J20: =IF(I20="",".",J19+I20) -> 583276.91
A21: =A20+1 -> 20 | B21: 44718 | C21: =IF(B21="","",YEAR(B21)) -> 2022 | D21: Tarifa Pacote de Serviços | E21: SAIDAS | F21: DESPESAS FINANCEIRAS | G21: Despesas Bancarias | H21: B.B. | I21: -66 | J21: =IF(I21="",".",J20+I21) -> 583210.91
A22: =A21+1 -> 21 | B22: 44735 | C22: =IF(B22="","",YEAR(B22)) -> 2022 | D22: Aplicaçao | F22: INVESTIMENTOS | G22: Aplicaçao | H22: B.B. | I22: -583210.91 | J22: =IF(I22="",".",J21+I22) -> -1.1641532e-10
A23: =A22+1 -> 22 | B23: 44748 | C23: =IF(B23="","",YEAR(B23)) -> 2022 | D23: Tarifa Pacote de Serviços | E23: SAIDAS | F23: DESPESAS FINANCEIRAS | G23: Despesas Bancarias | H23: B.B. | I23: -66 | J23: =IF(I23="",".",J22+I23) -> -66
A24: =A23+1 -> 23 | B24: 44748 | C24: =IF(B24="","",YEAR(B24)) -> 2022 | D24: Resgate | F24: INVESTIMENTOS | G24: Resgate | H24: B.B. | I24: 66 | J24: =IF(I24="",".",J23+I24) -> -1.1641532e-10
A25: =A24+1 -> 24 | B25: 44778 | C25: =IF(B25="","",YEAR(B25)) -> 2022 | D25: Tarifa Pacote de Serviços | E25: SAIDAS | F25: DESPESAS FINANCEIRAS | G25: Despesas Bancarias | H25: B.B. | I25: -66 | J25: =IF(I25="",".",J24+I25) -> -66
A26: =A25+1 -> 25 | B26: 44778 | C26: =IF(B26="","",YEAR(B26)) -> 2022 | D26: Resgate | F26: INVESTIMENTOS | G26: Resgate | H26: B.B. | I26: 66 | J26: =IF(I26="",".",J25+I26) -> -1.1641532e-10
A27: =A26+1 -> 26 | B27: 44809 | C27: =IF(B27="","",YEAR(B27)) -> 2022 | D27: Tarifa Pacote de Serviços | E27: SAIDAS | F27: DESPESAS FINANCEIRAS | G27: Despesas Bancarias | H27: B.B. | I27: -66 | J27: =IF(I27="",".",J26+I27) -> -66
A28: =A27+1 -> 27 | B28: 44809 | C28: =IF(B28="","",YEAR(B28)) -> 2022 | D28: Resgate | F28: INVESTIMENTOS | G28: Resgate | H28: B.B. | I28: 66 | J28: =IF(I28="",".",J27+I28) -> -1.1641532e-10
A29: =A28+1 -> 28 | B29: 44839 | C29: =IF(B29="","",YEAR(B29)) -> 2022 | D29: Tarifa Pacote de Serviços | E29: SAIDAS | F29: DESPESAS FINANCEIRAS | G29: Despesas Bancarias | H29: B.B. | I29: -66 | J29: =IF(I29="",".",J28+I29) -> -66
A30: =A29+1 -> 29 | B30: 44839 | C30: =IF(B30="","",YEAR(B30)) -> 2022 | D30: Resgate | F30: INVESTIMENTOS | G30: Resgate | H30: B.B. | I30: 66 | J30: =IF(I30="",".",J29+I30) -> -1.1641532e-10
A31: =A30+1 -> 30 | B31: 44872 | C31: =IF(B31="","",YEAR(B31)) -> 2022 | D31: Tarifa Pacote de Serviços | E31: SAIDAS | F31: DESPESAS FINANCEIRAS | G31: Despesas Bancarias | H31: B.B. | I31: -66 | J31: =IF(I31="",".",J30+I31) -> -66
A32: =A31+1 -> 31 | B32: 44872 | C32: =IF(B32="","",YEAR(B32)) -> 2022 | D32: Resgate | F32: INVESTIMENTOS | G32: Resgate | H32: B.B. | I32: 66 | J32: =IF(I32="",".",J31+I32) -> -1.1641532e-10
A33: =A32+1 -> 32 | B33: 44900 | C33: =IF(B33="","",YEAR(B33)) -> 2022 | D33: Tarifa Pacote de Serviços | E33: SAIDAS | F33: DESPESAS FINANCEIRAS | G33: Despesas Bancarias | H33: B.B. | I33: -66 | J33: =IF(I33="",".",J32+I33) -> -66
A34: =A33+1 -> 33 | B34: 44900 | C34: =IF(B34="","",YEAR(B34)) -> 2022 | D34: Resgate | F34: INVESTIMENTOS | G34: Resgate | H34: B.B. | I34: 66 | J34: =IF(I34="",".",J33+I34) -> -1.1641532e-10
A35: =A34+1 -> 34 | B35: 44918 | C35: =IF(B35="","",YEAR(B35)) -> 2022 | D35: 50% Traduzione giurata dello Statuto | E35: SAIDAS | F35: DESPESAS GERAIS | G35: Varias | H35: Antonio Francisco Alves Ro | I35: -1050 | J35: =IF(I35="",".",J34+I35) -> -1050
A36: =A35+1 -> 35 | B36: 44918 | C36: =IF(B36="","",YEAR(B36)) -> 2022 | D36: Resgate | F36: INVESTIMENTOS | G36: Resgate | H36: B.B. | I36: 1050 | J36: =IF(I36="",".",J35+I36) -> -1.1641532e-10
A37: =A36+1 -> 36 | B37: 44924 | C37: =IF(B37="","",YEAR(B37)) -> 2022 | D37: Transferencia recebida | E37: ENTRADAS | F37: LOCACAO | G37: Produtos | H37: JM EMPREENDIMENTOS IMOBILIARIO SCP LTDA | I37: 255109.77 | J37: =IF(I37="",".",J36+I37) -> 255109.77
A38: =A37+1 -> 37 | B38: 44931 | C38: =IF(B38="","",YEAR(B38)) -> 2023 | D38: Tarifa Pacote de Serviços | E38: SAIDAS | F38: DESPESAS FINANCEIRAS | G38: Despesas Bancarias | H38: B.B. | I38: -69 | J38: =IF(I38="",".",J37+I38) -> 255040.77
A39: =A38+1 -> 38 | B39: 44958 | C39: =IF(B39="","",YEAR(B39)) -> 2023 | D39: Aplicaçao | F39: INVESTIMENTOS | G39: Aplicaçao | H39: B.B. | I39: -255040.77 | J39: =IF(I39="",".",J38+I39) -> -1.1641532e-10
A40: =A39+1 -> 39 | B40: 44963 | C40: =IF(B40="","",YEAR(B40)) -> 2023 | D40: Tarifa Pacote de Serviços | E40: SAIDAS | F40: DESPESAS FINANCEIRAS | G40: Despesas Bancarias | H40: B.B. | I40: -69 | J40: =IF(I40="",".",J39+I40) -> -69
...

Sheet Pivot cons
A3: Sum of Total | B3: Etichette di colonna
A4: Etichette di riga | B4: 2021 | C4: 2022 | D4: 2023 | E4: 2024 | F4: 2025 | G4: 2026 | H4: Totale complessivo
A5: ENTRADAS
A6: LOCACAO
A7: Produtos | B7: 600000 | C7: 839056.88 | F7: 617509.26 | G7: 43156.04 | H7: 2099722.2
A8: LOCACAO Totale | B8: 600000 | C8: 839056.88 | F8: 617509.26 | G8: 43156.04 | H8: 2099722.2
A9: JUROS
A10: Receitas Financeiras | B10: 536.34 | C10: 33780.47 | D10: 90650.19 | E10: 80942.61 | F10: 135991.31 | G10: 141245.5 | H10: 483146.42
A11: JUROS Totale | B11: 536.34 | C11: 33780.47 | D11: 90650.19 | E11: 80942.61 | F11: 135991.31 | G11: 141245.5 | H11: 483146.42
A12: ENTRADAS Totale | B12: 600536.34 | C12: 872837.35 | D12: 90650.19 | E12: 80942.61 | F12: 753500.57 | G12: 184401.54 | H12: 2582868.6
A13: SAIDAS
A14: IMOBILIZACAO
A15: Terreno | B15: -600000 | H15: -600000
A16: IMOBILIZACAO Totale | B16: -600000 | H16: -600000
A17: DESPESAS FINANCEIRAS
A18: Despesas Bancarias | C18: -786 | D18: -831 | E18: -729 | F18: -925.6 | G18: -791.1 | H18: -4062.7
A19: DESPESAS FINANCEIRAS Totale | C19: -786 | D19: -831 | E19: -729 | F19: -925.6 | G19: -791.1 | H19: -4062.7
A20: DESPESAS TRIBUTARIAS
A21: Juros e Multa | C21: -23.37 | H21: -23.37
A22: Taxa de Localizaçao 2021 | C22: -72.87 | H22: -72.87
A23: Taxa de Localizaçao 2022 | C23: -320.78 | H23: -320.78
A24: Taxa de Localizaçao 2023 | E24: -408.82 | H24: -408.82
A25: Taxa de Localizaçao 2024 | E25: -408.78 | H25: -408.78
A26: Taxa de Localizaçao 2025 | F26: -378.61 | H26: -378.61
A27: Taxa de Localizaçao 2026 | G27: -398.75 | H27: -398.75
A28: IOF Bancario | B28: -445.05 | C28: -0.21 | H28: -445.26
A29: IRRF | B29: -20.5 | C29: -5609.93 | D29: -17894.58 | E29: -16073.35 | F29: -25469.15 | G29: -18588.53 | H29: -83656.04
A30: DESPESAS TRIBUTARIAS Totale | B30: -465.55 | C30: -6027.16 | D30: -17894.58 | E30: -16890.95 | F30: -25847.76 | G30: -18987.28 | H30: -86113.28
A31: DESPESAS GERAIS
A32: Varias | C32: -1050 | D32: -2050 | E32: -21475.47 | F32: -17822.03 | G32: -935.39 | H32: -43332.89
A33: Gestao Empresarial | F33: -15610 | G33: -21208.31 | H33: -36818.31
A34: Moveis Casa H | F34: -7482.84 | H34: -7482.84
A35: DESPESAS GERAIS Totale | C35: -1050 | D35: -2050 | E35: -21475.47 | F35: -40914.87 | G35: -22143.7 | H35: -87634.04
A36: CESSAO DE CREDITO
A37: Cessao de Credito | F37: -62000 | H37: -62000
A38: CESSAO DE CREDITO Totale | F38: -62000 | H38: -62000
A39: SAIDAS Totale | B39: -600465.55 | C39: -7863.16 | D39: -20775.58 | E39: -39095.42 | F39: -129688.23 | G39: -41922.08 | H39: -839810.02
A40: Totale complessivo | B40: 70.79 | C40: 864974.19 | D40: 69874.61 | E40: 41847.19 | F40: 623812.34 | G40: 142479.46 | H40: 1743058.6

Sheet Bilancio
A3: Empresa: | B3: SOMBRA RESORT BRASIL Sociedade Unipessoal Ltda
A4: CNPJ: | B4: 43.730.206/0001-80
A5: Insc. Junta Comercial | B5: 24200911503 | C5: 44469
A7: Banco: | B7: Banco do Brasil - Goianinha
A8: Agencia: | B8: 1066-9
A9: Conta: | B9: 48649-3
B11: Ano | C11: Conta Corrente | D11: Investimentos Fundos | E11: Total
B13: 44561 | C13: 0 | D13: 70.79 | E13: =C13+D13 -> 70.79
B15: 44926 | C15: 255109.77 | D15: 609935.21 | E15: =C15+D15 -> 865044.98
B17: 45291 | C17: 0 | D17: 934919.59 | E17: =C17+D17 -> 934919.59
B19: 45657 | C19: 0 | D19: 976766.78 | E19: =C19+D19 -> 976766.78
B21: 46022 | C21: 8856.39 | D21: 1591722.7 | E21: =C21+D21 -> 1600579.1
B23: 46387 | C23: 0 | D23: 0 | E23: =C23+D23 -> 0

Sheet Dati conto Brasile
B3: SOMBRA RESORT BRASIL Sociedad Unipessoal L.T.D.A.
B4: BRASIL
B6: CNPJ: | C6: 43.730.206/0001-80 | D6: 44469
B8: CONTA COM:
B10: BANCO DO BRASIL
B11: AGENCIA | C11: 1066-9
B12: GOIANINHA - R.N. BRASIL
B14: SOMBRA RESORT BRASIL Sociedad Unipessoal L.T.D.A.
B15: C/C | C15: 48649-3
B16: IBAN:
B17: SWIFT: | C17: BRAS BRRJ SBO
